[2017-05-03 10:47:34,672] data_manager [ERROR] __main__.py LINE 235:  sssssssssss
[2017-05-03 10:49:02,430] data_manager [ERROR] __main__.py LINE 237:  sssssssssss
[2017-05-03 10:49:02,431] data_manager [INFO] logger.py LINE 67:  ['sd', 'sere']
[2017-05-03 10:59:51,440] data_manager [ERROR] __main__.py LINE 236:  sssssssssss
